
[2025/09/24 10:37:31] Occur Error : 
 -File name: c:\Users\V1537224\AppData\Local\Programs\Python\Python313\Lib\site-packages\google\auth\transport\requests.py 
 -Function : __call__ 
 -Line Name: 194 
 -Error Content: HTTPSConnectionPool(host='oauth2.googleapis.com', port=443): Max retries exceeded with url: /token (Caused by ConnectTimeoutError(<urllib3.connection.HTTPSConnection object at 0x0000022076E03C50>, 'Connection to oauth2.googleapis.com timed out. (connect timeout=120)'))